Workbook

Sheet Instructions
A1: NCBA GROUP PLC — COMPREHENSIVE FINANCIAL MODEL
A2: Nairobi Securities Exchange | NSE: NCBA | Banking & Financial Services
A4: Company Overview: | B4: NCBA Group PLC is a full-service banking group listed on the NSE, operating in Kenya, Tanzania, Uganda, Rwanda, Côte d'Ivoire and Ghana. The Group offers retail, corporate and digital banking, insurance and investment services. FY2025 PAT: KES 23.4 bn.
A5: Ticker Symbol | B5: NSE: NCBA
A6: Sector | B6: Banking & Financial Services
A7: Reporting Currency | B7: Kenya Shillings (KES '000)
A8: Model Base Year | B8: FY2025 (Year ended 31 December 2025)
A9: Report Source | B9: NCBA Group PLC Annual Report & Financial Statements FY2025
A10: Auditors | B10: Deloitte & Touche LLP, Kenya
A11: Shares Outstanding | B11: 1,647,519,000 ordinary shares
A13: HOW TO USE THIS MODEL
A14: 1. Assumptions | B14: Set macro, growth, margin, WACC and valuation inputs (yellow cells = key drivers)
A15: 2. Income Statement | B15: Historical FY2024 & FY2025 actuals; 5-year projections auto-calculated
A16: 3. Balance Sheet | B16: Historical balance sheet with projected loan, deposit & equity growth
A17: 4. Cash Flow | B17: Operating, investing and financing cash flows — historical & projected
A18: 5. DCF Valuation | B18: FCFE-based discounted cash flow to intrinsic value per share
A19: 6. Multiples Valuation | B19: P/E, P/B, EV/EBITDA, Dividend Yield comparable multiples
A20: 7. Returns & MOIC | B20: IRR, NPV, ROI, MOIC from a 5-year equity investment perspective
A21: 8. Sensitivity Analysis | B21: Two-variable tables: WACC vs growth, entry/exit multiples, etc.
A22: 9. Summary | B22: Full investment recommendation and valuation bridge
A25: COLOR CODE CONVENTION
A26: Blue Text | B26: User inputs — modify for scenario analysis
A27: Black Text | B27: Formulas and calculated values
A28: Green Text | B28: Links pulling from another sheet in this workbook
A29: Yellow Highlight | B29: Key assumptions requiring attention

Sheet Assumptions
A1: NCBA GROUP PLC — VALUATION ASSUMPTIONS
A2: All values KES '000 unless stated | Blue = editable input | Yellow = key assumption
A4: A. COMPANY INFORMATION
A5: Company Name | B5: NCBA Group PLC
A6: Ticker Symbol | B6: 39.5
A7: Sector | B7: 1647.519
A8: Current Stock Price (KES) | B8: 1647.519 | C8: Source: NSE — indicative price
A9: Shares Outstanding (millions) | B9: 1,647.52 | C9: Source: NCBA AR FY2025, Note 20
A10: Market Capitalisation (KES mn) | B10: =B7*B8*1000 -> 2.7143189e+09 | C10: Calculated
A11: Financial Year End | B11: 31-Dec
A13: B. REVENUE & GROWTH ASSUMPTIONS
A14: NII Growth Rate — FY2026E | B14: 0.08 | C14: Normalization post rate cut cycle
A15: NII Growth Rate — FY2027E | B15: 0.09
A16: NII Growth Rate — FY2028E | B16: 0.09
A17: NII Growth Rate — FY2029E | B17: 0.1
A18: NII Growth Rate — FY2030E | B18: 0.1
A19: Non-Interest Income Growth — FY2026E | B19: 0.05
A20: Non-Interest Income Growth — FY2027E | B20: 0.06
A21: Non-Interest Income Growth — FY2028E | B21: 0.06
A22: Non-Interest Income Growth — FY2029E | B22: 0.07
A23: Non-Interest Income Growth — FY2030E | B23: 0.07
A24: Operating Expense Growth — FY2026E | B24: 0.1 | C24: Headcount + investment costs
A25: Operating Expense Growth — FY2027E | B25: 0.08
A26: Operating Expense Growth — FY2028E | B26: 0.08
A27: Operating Expense Growth — FY2029E | B27: 0.07
A28: Operating Expense Growth — FY2030E | B28: 0.07
A29: Credit Impairment / Net Operating Income | B29: 0.096 | C29: FY2025 basis: 6,902/71,832
A30: Loan Growth Rate (annual) | B30: 0.06
A31: Deposit Growth Rate (annual) | B31: 0.055
A32: Terminal Growth Rate (DCF) | B32: 0.045 | C32: Long-run nominal GDP
A34: C. MARGIN & VALUATION ASSUMPTIONS
A35: EBITDA Margin % | B35: 0.11 | C35: Approx. NII+NIInc-Opex/Total Income
A36: Effective Tax Rate % | B36: 0.161 | C36: FY2025 actual: 4,497/27,890
A37: Dividend Payout Ratio % | B37: 0.6 | C37: FY2025: DPS 7.10 / EPS 14.20
A38: Target ROE | B38: 0.185
A39: WACC / Discount Rate % | B39: 0.14 | C39: See WACC breakdown below
A40: Entry Share Price (KES) | B40: 39.5 | C40: Current NSE market price
A41: Target P/E Multiple | B41: 8 | C41: KCB, Equity peer comps
A42: Target P/B Multiple | B42: 1.2
A43: Target EV/EBITDA Multiple | B43: 5.5
...

Sheet Income Statement
A1: NCBA GROUP PLC — CONSOLIDATED INCOME STATEMENT
A2: KES '000 | Source: Annual Report FY2025, pp.19-20 | Projections driven by Assumptions sheet
A4: LINE ITEM | B4: FY2024 Actual | C4: FY2025 Actual | D4: FY2026E | E4: FY2027E | F4: FY2028E | G4: FY2029E | H4: FY2030E | I4: YoY FY25 vs FY24
A5: INTEREST INCOME & EXPENSE
A6: Interest Income | B6: 88620061 | C6: 81764856 | D6: =C6*(1+Assumptions!$B$14) -> 88306044 | E6: =D6*(1+Assumptions!$B$15) -> 96253588 | F6: =E6*(1+Assumptions!$B$16) -> 1.0491641e+08 | G6: =F6*(1+Assumptions!$B$17) -> 1.1540805e+08 | H6: =G6*(1+Assumptions!$B$18) -> 1.2694886e+08 | I6: =(C6-B6)/ABS(B6) -> -0.077355002
A7: Interest Expense | B7: -41173285 | C7: -24053334 | D7: =C7*(1+Assumptions!$B$14) -> -25977601 | E7: =D7*(1+Assumptions!$B$15) -> -28315585 | F7: =E7*(1+Assumptions!$B$16) -> -30863987 | G7: =F7*(1+Assumptions!$B$17) -> -33950386 | H7: =G7*(1+Assumptions!$B$18) -> -37345425 | I7: =(C7-B7)/ABS(B7) -> 0.41580241
A8: Net Interest Income (NII) | B8: 47446776 | C8: 57711522 | D8: =D6+D7 -> 62328444 | E8: =E6+E7 -> 67938004 | F8: =F6+F7 -> 74052424 | G8: =G6+G7 -> 81457666 | H8: =H6+H7 -> 89603433 | I8: =(C8-B8)/ABS(B8) -> 0.21634233
A10: NON-INTEREST INCOME
A11: Fees & Commission Income | B11: 6221872 | C11: 6034076 | D11: =C11*(1+Assumptions!$B$19) -> 6335779.8 | E11: =D11*(1+Assumptions!$B$20) -> 6715926.6 | F11: =E11*(1+Assumptions!$B$21) -> 7118882.2 | G11: =F11*(1+Assumptions!$B$22) -> 7617203.9 | H11: =G11*(1+Assumptions!$B$23) -> 8150408.2 | I11: =(C11-B11)/ABS(B11) -> -0.030183199
A12: Fees & Commission Expense | B12: -641293 | C12: -637585 | D12: =C12*(1+Assumptions!$B$19) -> -669464.25 | E12: =D12*(1+Assumptions!$B$20) -> -709632.1 | F12: =E12*(1+Assumptions!$B$21) -> -752210.03 | G12: =F12*(1+Assumptions!$B$22) -> -804864.73 | H12: =G12*(1+Assumptions!$B$23) -> -861205.26 | I12: =(C12-B12)/ABS(B12) -> 0.0057820684
A13: Net Fees & Commission Income | B13: 5580579 | C13: 5396491 | D13: =D11+D12 -> 5666315.5 | E13: =E11+E12 -> 6006294.5 | F13: =F11+F12 -> 6366672.2 | G13: =G11+G12 -> 6812339.2 | H13: =H11+H12 -> 7289202.9 | I13: =(C13-B13)/ABS(B13) -> -0.032987258
A14: Insurance Revenue (net) | B14: 1221941 | C14: 1591120 | D14: =C14*(1+Assumptions!$B$19) -> 1670676 | E14: =D14*(1+Assumptions!$B$20) -> 1770916.6 | F14: =E14*(1+Assumptions!$B$21) -> 1877171.6 | G14: =F14*(1+Assumptions!$B$22) -> 2008573.6 | H14: =G14*(1+Assumptions!$B$23) -> 2149173.7 | I14: =(C14-B14)/ABS(B14) -> 0.30212506
A15: Net Foreign Exchange Income | B15: 6249763 | C15: 5079771 | D15: =C15*(1+Assumptions!$B$19) -> 5333759.5 | E15: =D15*(1+Assumptions!$B$20) -> 5653785.1 | F15: =E15*(1+Assumptions!$B$21) -> 5993012.2 | G15: =F15*(1+Assumptions!$B$22) -> 6412523.1 | H15: =G15*(1+Assumptions!$B$23) -> 6861399.7 | I15: =(C15-B15)/ABS(B15) -> -0.18720582
A16: Other Income & FV Gains | B16: 2234229 | C16: 2677392 | D16: =C16*(1+Assumptions!$B$19) -> 2811261.6 | E16: =D16*(1+Assumptions!$B$20) -> 2979937.3 | F16: =E16*(1+Assumptions!$B$21) -> 3158733.5 | G16: =F16*(1+Assumptions!$B$22) -> 3379844.9 | H16: =G16*(1+Assumptions!$B$23) -> 3616434 | I16: =(C16-B16)/ABS(B16) -> 0.19835165
A17: Net Reinsurance & Insurance Finance | B17: -742909 | C17: -624601 | D17: =C17*(1+Assumptions!$B$19) -> -655831.05 | E17: =D17*(1+Assumptions!$B$20) -> -695180.91 | F17: =E17*(1+Assumptions!$B$21) -> -736891.77 | G17: =F17*(1+Assumptions!$B$22) -> -788474.19 | H17: =G17*(1+Assumptions!$B$23) -> -843667.38 | I17: =(C17-B17)/ABS(B17) -> 0.15924965
A18: Non-Interest Income | B18: 14543565 | C18: 14120431 | D18: =SUM(D11:D17) -> 20492497 | E18: =SUM(E11:E17) -> 21722047 | F18: =SUM(F11:F17) -> 23025370 | G18: =SUM(G11:G17) -> 24637146 | H18: =SUM(H11:H17) -> 26361746 | I18: =(C18-B18)/ABS(B18) -> -0.029094242
A20: Net Operating Income | B20: 61990341 | C20: 71831953 | D20: =D8+D18 -> 82820941 | E20: =E8+E18 -> 89660051 | F20: =F8+F18 -> 97077794 | G20: =G8+G18 -> 1.0609481e+08 | H20: =H8+H18 -> 1.1596518e+08 | I20: =(C20-B20)/ABS(B20) -> 0.15876041
A22: OPERATING EXPENSES
A23: Staff Costs | B23: -18230000 | C23: -21200000 | D23: =C23*(1+Assumptions!$B$24) -> -23320000 | E23: =D23*(1+Assumptions!$B$25) -> -25185600 | F23: =E23*(1+Assumptions!$B$26) -> -27200448 | G23: =F23*(1+Assumptions!$B$27) -> -29104479 | H23: =G23*(1+Assumptions!$B$28) -> -31141793 | I23: =(C23-B23)/ABS(B23) -> -0.16291827
A24: Other Operating Expenses | B24: -13659883 | C24: -15931182 | D24: =C24*(1+Assumptions!$B$24) -> -17524300 | E24: =D24*(1+Assumptions!$B$25) -> -18926244 | F24: =E24*(1+Assumptions!$B$26) -> -20440344 | G24: =F24*(1+Assumptions!$B$27) -> -21871168 | H24: =G24*(1+Assumptions!$B$28) -> -23402150 | I24: =(C24-B24)/ABS(B24) -> -0.16627514
A25: Total Operating Expenses | B25: -31889883 | C25: -37131182 | D25: =D23+D24 -> -40844300 | E25: =E23+E24 -> -44111844 | F25: =F23+F24 -> -47640792 | G25: =G23+G24 -> -50975647 | H25: =H23+H24 -> -54543942 | I25: =(C25-B25)/ABS(B25) -> -0.16435617
A27: Operating Profit (Pre-Impairment) | B27: 30100458 | C27: 34700771 | D27: =D20+D25 -> 41976641 | E27: =E20+E25 -> 45548207 | F27: =F20+F25 -> 49437002 | G27: =G20+G25 -> 55119165 | H27: =H20+H25 -> 61421237 | I27: =(C27-B27)/ABS(B27) -> 0.15283199
A29: Credit Impairment Losses | B29: -5046435 | C29: -6902153 | D29: =-Assumptions!$B$29*D20 -> -7950810.3 | E29: =-Assumptions!$B$29*E20 -> -8607364.9 | F29: =-Assumptions!$B$29*F20 -> -9319468.2 | G29: =-Assumptions!$B$29*G20 -> -10185102 | H29: =-Assumptions!$B$29*H20 -> -11132657 | I29: =(C29-B29)/ABS(B29) -> -0.36772851
A30: Share of Associates' Profit | B30: 87025 | C30: 91612 | D30: =C30*1.03 -> 94360.36 | E30: =D30*1.03 -> 97191.171 | F30: =E30*1.03 -> 100106.91 | G30: =F30*1.03 -> 103110.11 | H30: =G30*1.03 -> 106203.42 | I30: =(C30-B30)/ABS(B30) -> 0.052708992
A31: Profit Before Tax (PBT) | B31: 25141048 | C31: 27890230 | D31: =D27+D29+D30 -> 34120191 | E31: =E27+E29+E30 -> 37038033 | F31: =F27+F29+F30 -> 40217641 | G31: =G27+G29+G30 -> 45037173 | H31: =H27+H29+H30 -> 50394783 | I31: =(C31-B31)/ABS(B31) -> 0.10935033
A32: Income Tax Expense | B32: -3275281 | C32: -4496712 | D32: =-Assumptions!$B$36*D31 -> -5493350.7 | E32: =-Assumptions!$B$36*E31 -> -5963123.3 | F32: =-Assumptions!$B$36*F31 -> -6475040.2 | G32: =-Assumptions!$B$36*G31 -> -7250984.9 | H32: =-Assumptions!$B$36*H31 -> -8113560 | I32: =(C32-B32)/ABS(B32) -> -0.37292403
A33: Profit for the Year (PAT) | B33: 21865767 | C33: 23393518 | D33: =D31+D32 -> 28626840 | E33: =E31+E32 -> 31074910 | F33: =F31+F32 -> 33742601 | G33: =G31+G32 -> 37786188 | H33: =H31+H32 -> 42281223 | I33: =(C33-B33)/ABS(B33) -> 0.069869536
A35: PER SHARE DATA
A36: EPS — Basic & Diluted (KES) | B36: 13.28 | C36: 14.2 | D36: =D33/1647519 -> 17.375727 | E36: =E33/1647519 -> 18.86164 | F36: =F33/1647519 -> 20.480857 | G36: =G33/1647519 -> 22.935206 | H36: =H33/1647519 -> 25.663572 | I36: =(C36-B36)/ABS(B36) -> 0.069277108
A37: DPS — Total Declared (KES) | B37: 5.5 | C37: 7.1 | D37: =D36*Assumptions!$B$37 -> 10.425436 | E37: =E36*Assumptions!$B$37 -> 11.316984 | F37: =F36*Assumptions!$B$37 -> 12.288514 | G37: =G36*Assumptions!$B$37 -> 13.761124 | H37: =H36*Assumptions!$B$37 -> 15.398143 | I37: =(C37-B37)/ABS(B37) -> 0.29090909
A38: Shares Outstanding ('000) | B38: 1647519 | C38: 1647519 | D38: =1647519 -> 1647519 | E38: =1647519 -> 1647519 | F38: =1647519 -> 1647519 | G38: =1647519 -> 1647519 | H38: =1647519 -> 1647519 | I38: =(C38-B38)/ABS(B38) -> 0
A40: KEY RATIOS
A41: NIM (NII / Net Operating Income) | B41: 0.077 | C41: 0.087 | D41: =D8/D20 -> 0.75256865 | E41: =E8/E20 -> 0.75772881 | F41: =F8/F20 -> 0.76281527 | G41: =G8/G20 -> 0.76778181 | H41: =H8/H20 -> 0.77267533 | I41: =(C41-B41)/ABS(B41) -> 0.12987013
A42: Cost-to-Income Ratio | B42: 0.5145 | C42: 0.517 | D42: =ABS(D25)/D20 -> 0.49316392 | E42: =ABS(E25)/E20 -> 0.49198995 | F42: =ABS(F25)/F20 -> 0.4907486 | G42: =ABS(G25)/G20 -> 0.48047257 | H42: =ABS(H25)/H20 -> 0.47034759 | I42: =(C42-B42)/ABS(B42) -> 0.0048590865
A43: Effective Tax Rate | B43: 0.1302 | C43: 0.1612 | D43: =ABS(D32)/D31 -> 0.161 | E43: =ABS(E32)/E31 -> 0.161 | F43: =ABS(F32)/F31 -> 0.161 | G43: =ABS(G32)/G31 -> 0.161 | H43: =ABS(H32)/H31 -> 0.161 | I43: =(C43-B43)/ABS(B43) -> 0.23809524

Sheet Balance Sheet
A1: NCBA GROUP PLC — CONSOLIDATED BALANCE SHEET
A2: KES '000 | Source: Annual Report FY2025, p.21 | Projections based on Assumptions sheet
A4: LINE ITEM | B4: FY2024 Actual | C4: FY2025 Actual | D4: FY2026E | E4: FY2027E | F4: FY2028E | G4: FY2029E | H4: FY2030E
A5: ASSETS
A6: Cash & Balances with Central Banks | B6: 43679381 | C6: 63774068 | D6: =C6*1.05 -> 66962771 | E6: =D6*1.05 -> 70310910 | F6: =E6*1.05 -> 73826455 | G6: =F6*1.05 -> 77517778 | H6: =G6*1.05 -> 81393667
A7: Items in Course of Collection | B7: 553733 | C7: 687951 | D7: =C7*1.03 -> 708589.53 | E7: =D7*1.03 -> 729847.22 | F7: =E7*1.03 -> 751742.63 | G7: =F7*1.03 -> 774294.91 | H7: =G7*1.03 -> 797523.76
A8: Due from Banking Institutions | B8: 52956080 | C8: 51367772 | D8: =C8*0.99 -> 50854094 | E8: =D8*0.99 -> 50345553 | F8: =E8*0.99 -> 49842098 | G8: =F8*0.99 -> 49343677 | H8: =G8*0.99 -> 48850240
A9: Government Securities | B9: 207516292 | C9: 221551079 | D9: =C9*1.05 -> 2.3262863e+08 | E9: =D9*1.05 -> 2.4426006e+08 | F9: =E9*1.05 -> 2.5647307e+08 | G9: =F9*1.05 -> 2.6929672e+08 | H9: =G9*1.05 -> 2.8276156e+08
A10: Investment Securities | B10: 15226830 | C10: 15512628 | D10: =C10*1.03 -> 15978007 | E10: =D10*1.03 -> 16457347 | F10: =E10*1.03 -> 16951067 | G10: =F10*1.03 -> 17459599 | H10: =G10*1.03 -> 17983387
A11: Customer Loans & Advances (net) | B11: 293932350 | C11: 306917975 | D11: =C11*(1+Assumptions!$B$30) -> 3.2533305e+08 | E11: =D11*(1+Assumptions!$B$30) -> 3.4485304e+08 | F11: =E11*(1+Assumptions!$B$30) -> 3.6554422e+08 | G11: =F11*(1+Assumptions!$B$30) -> 3.8747687e+08 | H11: =G11*(1+Assumptions!$B$30) -> 4.1072548e+08
A12: Other Assets & Derivatives | B12: 45414083 | C12: 49610431 | D12: =C12*1.05 -> 52090953 | E12: =D12*1.05 -> 54695500 | F12: =E12*1.05 -> 57430275 | G12: =F12*1.05 -> 60301789 | H12: =G12*1.05 -> 63316878
A13: Intangible Assets & Goodwill | B13: 7489118 | C13: 7297963 | D13: =C13*0.97 -> 7079024.1 | E13: =D13*0.97 -> 6866653.4 | F13: =E13*0.97 -> 6660653.8 | G13: =F13*0.97 -> 6460834.2 | H13: =G13*0.97 -> 6267009.1
A14: Property, Equipment & ROU | B14: 11786042 | C14: 11568785 | D14: =C14*1.02 -> 11800161 | E14: =D14*1.02 -> 12036164 | F14: =E14*1.02 -> 12276887 | G14: =F14*1.02 -> 12522425 | H14: =G14*1.02 -> 12772873
A15: Deferred Tax & Other Long-term | B15: 13380830 | C15: 13371310 | D15: =C15*1 -> 13371310 | E15: =D15*1 -> 13371310 | F15: =E15*1 -> 13371310 | G15: =F15*1 -> 13371310 | H15: =G15*1 -> 13371310
A16: TOTAL ASSETS | B16: 665943764 | C16: 716047157 | D16: =SUM(D6:D15) -> 7.768066e+08 | E16: =SUM(E6:E15) -> 8.1392639e+08 | F16: =SUM(F6:F15) -> 8.5312778e+08 | G16: =SUM(G6:G15) -> 8.945253e+08 | H16: =SUM(H6:H15) -> 9.3823993e+08
A18: LIABILITIES
A19: Customer Deposits | B19: 502016493 | C19: 531866221 | D19: =C19*(1+Assumptions!$B$31) -> 5.6111886e+08 | E19: =D19*(1+Assumptions!$B$31) -> 5.919804e+08 | F19: =E19*(1+Assumptions!$B$31) -> 6.2453932e+08 | G19: =F19*(1+Assumptions!$B$31) -> 6.5888899e+08 | H19: =G19*(1+Assumptions!$B$31) -> 6.9512788e+08
A20: Due to Banking Institutions | B20: 13407659 | C20: 10337119 | D20: =C20*0.9 -> 9303407.1 | E20: =D20*0.9 -> 8373066.4 | F20: =E20*0.9 -> 7535759.8 | G20: =F20*0.9 -> 6782183.8 | H20: =G20*0.9 -> 6103965.4
A21: Borrowings | B21: 10172225 | C21: 7565293 | D21: =C21*0.85 -> 6430499 | E21: =D21*0.85 -> 5465924.2 | F21: =E21*0.85 -> 4646035.6 | G21: =F21*0.85 -> 3949130.2 | H21: =G21*0.85 -> 3356760.7
A22: Other Liabilities & Insurance | B22: 30582085 | C22: 34861067 | D22: =C22*1.08 -> 37649952 | E22: =D22*1.08 -> 40661949 | F22: =E22*1.08 -> 43914904 | G22: =F22*1.08 -> 47428097 | H22: =G22*1.08 -> 51222345
A23: Tax Payable & Lease Liabilities | B23: 4178301 | C23: 7174223 | D23: =C23*1.02 -> 7317707.5 | E23: =D23*1.02 -> 7464061.6 | F23: =E23*1.02 -> 7613342.8 | G23: =F23*1.02 -> 7765609.7 | H23: =G23*1.02 -> 7920921.9
A24: TOTAL LIABILITIES | B24: 556229015 | C24: 588621591 | D24: =SUM(D19:D23) -> 6.2182043e+08 | E24: =SUM(E19:E23) -> 6.539454e+08 | F24: =SUM(F19:F23) -> 6.8824937e+08 | G24: =SUM(G19:G23) -> 7.2481401e+08 | H24: =SUM(H19:H23) -> 7.6373187e+08
A26: SHAREHOLDERS' EQUITY
A27: Share Capital | B27: 8237598 | C27: 8237598 | D27: =C27 -> 8237598 | E27: =D27 -> 8237598 | F27: =E27 -> 8237598 | G27: =F27 -> 8237598 | H27: =G27 -> 8237598
A28: Share Premium | B28: 21424322 | C28: 21424322 | D28: =C28 -> 21424322 | E28: =D28 -> 21424322 | F28: =E28 -> 21424322 | G28: =F28 -> 21424322 | H28: =G28 -> 21424322
A29: Retained Earnings & Reserves | B29: 80020429 | C29: 90214071 | D29: =C29+'Income Statement'!D33-'Income Statement'!D37*1647519 -> 1.0166481e+08 | E29: =D29+'Income Statement'!E33-'Income Statement'!E37*1647519 -> 1.1409477e+08 | F29: =E29+'Income Statement'!F33-'Income Statement'!F37*1647519 -> 1.2759181e+08 | G29: =F29+'Income Statement'!G33-'Income Statement'!G37*1647519 -> 1.4270629e+08 | H29: =G29+'Income Statement'!H33-'Income Statement'!H37*1647519 -> 1.5961878e+08
A30: Non-Controlling Interests & Other | B30: -15372 | C30: -29015 | D30: =C30*1.05 -> -30465.75 | E30: =D30*1.05 -> -31989.037 | F30: =E30*1.05 -> -33588.489 | G30: =F30*1.05 -> -35267.914 | H30: =G30*1.05 -> -37031.31
A31: TOTAL SHAREHOLDERS' EQUITY | B31: 109714749 | C31: 127425566 | D31: =SUM(D27:D30) -> 1.3129626e+08 | E31: =SUM(E27:E30) -> 1.437247e+08 | F31: =SUM(F27:F30) -> 1.5722014e+08 | G31: =SUM(G27:G30) -> 1.7233294e+08 | H31: =SUM(H27:H30) -> 1.8924366e+08
A32: TOTAL LIABILITIES & EQUITY | B32: 665943764 | C32: 716047157 | D32: =D24+D30 -> 6.2178996e+08 | E32: =E24+E30 -> 6.5391341e+08 | F32: =F24+F30 -> 6.8821578e+08 | G32: =G24+G30 -> 7.2477874e+08 | H32: =H24+H30 -> 7.6369484e+08
A34: KEY BALANCE SHEET RATIOS
A35: Loan-to-Deposit Ratio | B35: =B11/B19 -> 0.58550337 | C35: =C11/C19 -> 0.5770586 | D35: =D11/D19 -> 0.57979347 | E35: =E11/E19 -> 0.58254131 | F35: =F11/F19 -> 0.58530217 | G35: =G11/G19 -> 0.58807611 | H35: =H11/H19 -> 0.5908632
A36: Equity / Total Assets | B36: =B30/B15 -> -0.0011488077 | C36: =C30/C15 -> -0.0021699445 | D36: =D30/D15 -> -0.0022784417 | E36: =E30/E15 -> -0.0023923638 | F36: =F30/F15 -> -0.002511982 | G36: =G30/G15 -> -0.002637581 | H36: =H30/H15 -> -0.0027694601
A37: Loans / Total Assets | B37: =B11/B15 -> 21.966675 | C37: =C11/C15 -> 22.953471 | D37: =D11/D15 -> 24.330679 | E37: =E11/E15 -> 25.79052 | F37: =F11/F15 -> 27.337951 | G37: =G11/G15 -> 28.978228 | H37: =H11/H15 -> 30.716922

Sheet Cash Flow Statement
A1: NCBA GROUP PLC — CONSOLIDATED CASH FLOW STATEMENT
A2: KES '000 | Source: Annual Report FY2025, p.25 | FY2026E+ projected
A4: LINE ITEM | B4: FY2024 Actual | C4: FY2025 Actual | D4: FY2026E | E4: FY2027E | F4: FY2028E | G4: FY2029E | H4: FY2030E
A5: OPERATING ACTIVITIES
A6: Profit Before Tax (PBT) | B6: 25141048 | C6: 27890230 | D6: ='Income Statement'!D31 -> 34120191 | E6: ='Income Statement'!E31 -> 37038033 | F6: ='Income Statement'!F31 -> 40217641 | G6: ='Income Statement'!G31 -> 45037173 | H6: ='Income Statement'!H31 -> 50394783
A7: Depreciation & Amortisation | B7: 500000 | C7: 600000 | D7: =C7*1.05 -> 630000 | E7: =D7*1.05 -> 661500 | F7: =E7*1.05 -> 694575 | G7: =F7*1.05 -> 729303.75 | H7: =G7*1.05 -> 765768.94
A8: Other Non-Cash Adjustments | B8: -39513142 | C8: -47400221 | D8: =C8*1.05 -> -49770232 | E8: =D8*1.05 -> -52258744 | F8: =E8*1.05 -> -54871681 | G8: =F8*1.05 -> -57615265 | H8: =G8*1.05 -> -60496028
A9: Changes in Working Capital | B9: -43474189 | C9: 8369234 | D9: =C9*0.95 -> 7950772.3 | E9: =D9*0.95 -> 7553233.7 | F9: =E9*0.95 -> 7175572 | G9: =F9*0.95 -> 6816793.4 | H9: =G9*0.95 -> 6475953.7
A10: Income Tax Paid | B10: -3983752 | C10: -1355814 | D10: =-Assumptions!$B$36*'Income Statement'!D31 -> -5493350.7 | E10: =-Assumptions!$B$36*'Income Statement'!E31 -> -5963123.3 | F10: =-Assumptions!$B$36*'Income Statement'!F31 -> -6475040.2 | G10: =-Assumptions!$B$36*'Income Statement'!G31 -> -7250984.9 | H10: =-Assumptions!$B$36*'Income Statement'!H31 -> -8113560
A11: Interest Received | B11: 88067693 | C11: 74342470 | D11: ='Income Statement'!D8*1.15 -> 71677710 | E11: ='Income Statement'!E8*1.15 -> 78128704 | F11: ='Income Statement'!F8*1.15 -> 85160288 | G11: ='Income Statement'!G8*1.15 -> 93676316 | H11: ='Income Statement'!H8*1.15 -> 1.0304395e+08
A12: Interest Paid | B12: -40694997 | C12: -23614078 | D12: =C12*0.92 -> -21724952 | E12: =D12*0.92 -> -19986956 | F12: =E12*0.92 -> -18387999 | G12: =F12*0.92 -> -16916959 | H12: =G12*0.92 -> -15563602
A13: Net Cash from Operating Activities | B13: -14457339 | C13: 38231821 | D13: =SUM(D6:D12) -> 37390139 | E13: =SUM(E6:E12) -> 45172648 | F13: =SUM(F6:F12) -> 53513355 | G13: =SUM(G6:G12) -> 64476378 | H13: =SUM(H6:H12) -> 76507263
A15: INVESTING ACTIVITIES
A16: Purchase of Government Securities | B16: -73668934 | C16: -121450266 | D16: =C16*1.05 -> -1.2752278e+08 | E16: =D16*1.05 -> -1.3389892e+08 | F16: =E16*1.05 -> -1.4059386e+08 | G16: =F16*1.05 -> -1.4762356e+08 | H16: =G16*1.05 -> -1.5500474e+08
A17: Proceeds from Matured Gov. Securities | B17: 90759782 | C17: 114597561 | D17: =C17*1.04 -> 1.1918146e+08 | E17: =D17*1.04 -> 1.2394872e+08 | F17: =E17*1.04 -> 1.2890667e+08 | G17: =F17*1.04 -> 1.3406294e+08 | H17: =G17*1.04 -> 1.3942546e+08
A18: Purchase / Sale of Investments (net) | B18: -1644590 | C18: -495846 | D18: =C18*0.98 -> -485929.08 | E18: =D18*0.98 -> -476210.5 | F18: =E18*0.98 -> -466686.29 | G18: =F18*0.98 -> -457352.56 | H18: =G18*0.98 -> -448205.51
A19: Capital Expenditure (Capex) | B19: -2696205 | C19: -1562921 | D19: =C19*1.03 -> -1609808.6 | E19: =D19*1.03 -> -1658102.9 | F19: =E19*1.03 -> -1707846 | G19: =F19*1.03 -> -1759081.4 | H19: =G19*1.03 -> -1811853.8
A20: Other Investing Flows | B20: 32830 | C20: 33896 | D20: =C20*1 -> 33896 | E20: =D20*1 -> 33896 | F20: =E20*1 -> 33896 | G20: =F20*1 -> 33896 | H20: =G20*1 -> 33896
A21: Net Cash from Investing Activities | B21: 15164656 | C21: -9882207 | D21: =SUM(D16:D20) -> -10403158 | E21: =SUM(E16:E20) -> -12050614 | F21: =SUM(F16:F20) -> -13827830 | G21: =SUM(G16:G20) -> -15743158 | H21: =SUM(H16:H20) -> -17805443
A23: FINANCING ACTIVITIES
A24: Dividends Paid | B24: -8649476 | C24: -9473237 | D24: =-'Income Statement'!D37*1647519 -> -17176104 | E24: =-'Income Statement'!E37*1647519 -> -18644946 | F24: =-'Income Statement'!F37*1647519 -> -20245560 | G24: =-'Income Statement'!G37*1647519 -> -22671713 | H24: =-'Income Statement'!H37*1647519 -> -25368734
A25: Repayment of Borrowings | B25: -1854207 | C25: -2306472 | D25: =C25*0.95 -> -2191148.4 | E25: =D25*0.95 -> -2081591 | F25: =E25*0.95 -> -1977511.4 | G25: =F25*0.95 -> -1878635.9 | H25: =G25*0.95 -> -1784704.1
A26: Lease Liability Payments | B26: -865022 | C26: -979929 | D26: =C26*0.98 -> -960330.42 | E26: =D26*0.98 -> -941123.81 | F26: =E26*0.98 -> -922301.34 | G26: =F26*0.98 -> -903855.31 | H26: =G26*0.98 -> -885778.2
A27: Proceeds from New Borrowings | B27: 6843499 | C27: 0 | D27: =0 -> 0 | E27: =0 -> 0 | F27: =0 -> 0 | G27: =0 -> 0 | H27: =0 -> 0
A28: Net Cash from Financing Activities | B28: -4525206 | C28: -12759638 | D28: =SUM(D24:D27) -> -20327583 | E28: =SUM(E24:E27) -> -21667661 | F28: =SUM(F24:F27) -> -23145373 | G28: =SUM(G24:G27) -> -25454204 | H28: =SUM(H24:H27) -> -28039216
A30: NET CHANGE IN CASH | B30: -3817889 | C30: 15589976 | D30: =D13+D21+D28 -> 6659398.5 | E30: =E13+E21+E28 -> 11454374 | F30: =F13+F21+F28 -> 16540153 | G30: =G13+G21+G28 -> 23279016 | H30: =H13+H21+H28 -> 30662604
A31: Opening Cash & Equivalents | B31: 90504283 | C31: 87178442 | D31: =C30+C31 -> 102768418 | E31: =D30+D31 -> 1.0942782e+08 | F31: =E30+E31 -> 1.2088219e+08 | G31: =F30+F31 -> 1.3742234e+08 | H31: =G30+G31 -> 1.6070136e+08
A32: FX Difference on Cash | B32: 492048 | C32: -235021 | D32: =0 -> 0 | E32: =0 -> 0 | F32: =0 -> 0 | G32: =0 -> 0 | H32: =0 -> 0
A33: CLOSING CASH & EQUIVALENTS | B33: 87178442 | C33: 102533397 | D33: =D30+D31+D32 -> 1.0942782e+08 | E33: =E30+E31+E32 -> 1.2088219e+08 | F33: =F30+F31+F32 -> 1.3742234e+08 | G33: =G30+G31+G32 -> 1.6070136e+08 | H33: =H30+H31+H32 -> 1.9136396e+08

Sheet DCF Valuation
A1: NCBA GROUP PLC — DCF VALUATION
A2: All amounts KES '000 except per-share values | FCFE Discounted Cash Flow Approach
A4: PROJECTION PERIOD | B4: Year 1 (FY2026E) | C4: Year 2 (FY2027E) | D4: Year 3 (FY2028E) | E4: Year 4 (FY2029E) | F4: Year 5 (FY2030E)
A5: Net Profit (PAT) — from Income Statement | B5: ='Income Statement'!D33 -> 28626840 | C5: ='Income Statement'!E33 -> 31074910 | D5: ='Income Statement'!F33 -> 33742601 | E5: ='Income Statement'!G33 -> 37786188 | F5: ='Income Statement'!H33 -> 42281223
A6: Add: Depreciation & Amortisation | B6: ='Income Statement'!D8*0.012 -> 747941.33 | C6: =B6*1.05 -> 785338.39 | D6: =C6*1.05 -> 824605.31 | E6: =D6*1.05 -> 865835.58 | F6: =E6*1.05 -> 909127.36
A7: Less: Capital Expenditure | B7: =-'Cash Flow Statement'!B19 -> 2696205 | C7: =B7*1.03 -> 2777091.1 | D7: =C7*1.03 -> 2860403.9 | E7: =D7*1.03 -> 2946216 | F7: =E7*1.03 -> 3034602.5
A8: Less: Change in Net Working Capital | B8: =-Assumptions!$B$30*'Income Statement'!D20*0.02 -> -99385.129 | C8: =-Assumptions!$B$30*'Income Statement'!E20*0.02 -> -107592.06 | D8: =-Assumptions!$B$30*'Income Statement'!F20*0.02 -> -116493.35 | E8: =-Assumptions!$B$30*'Income Statement'!G20*0.02 -> -127313.77 | F8: =-Assumptions!$B$30*'Income Statement'!H20*0.02 -> -139158.21
A9: FREE CASH FLOW TO EQUITY (FCFE) | B9: =B5+B6-B7-B8 -> 26777962 | C9: =C5+C6-C7-C8 -> 29190749 | D9: =D5+D6-D7-D8 -> 31823295 | E9: =E5+E6-E7-E8 -> 35833122 | F9: =F5+F6-F7-F8 -> 40294906
A11: Discount Period | B11: 1 | C11: 2 | D11: 3 | E11: 4 | F11: 5
A12: Discount Factor (WACC) | B12: =1/(1+Assumptions!$B$39)^1 -> 0.87719298 | C12: =1/(1+Assumptions!$B$39)^2 -> 0.76946753 | D12: =1/(1+Assumptions!$B$39)^3 -> 0.67497152 | E12: =1/(1+Assumptions!$B$39)^4 -> 0.59208028 | F12: =1/(1+Assumptions!$B$39)^5 -> 0.51936866
A13: Present Value of FCFE | B13: =B9*B12 -> 23489440 | C13: =C9*C12 -> 22461333 | D13: =D9*D12 -> 21479818 | E13: =E9*E12 -> 21216085 | F13: =F9*F12 -> 20927911
A15: TERMINAL VALUE CALCULATION
A16: Terminal Year FCFE (FY2030 × (1+g)) | B16: =G9*(1+Assumptions!$B$32) -> 0
A17: Terminal Value (Gordon Growth Model) | B17: =B16/(Assumptions!$B$39-Assumptions!$B$32) -> 0
A18: PV of Terminal Value | B18: =B17/((1+Assumptions!$B$39)^5) -> 0
A20: VALUATION SUMMARY
A21: Sum of PV of FCFEs (FY2026–FY2030) | B21: =SUM(B13:F13) -> 1.0957459e+08
A22: PV of Terminal Value | B22: =B18 -> 0
A23: Enterprise Value (EV) | B23: =B21+B22 -> 1.0957459e+08
A24: Less: Borrowings (Debt) | B24: =-7565293 -> -7565293
A25: Add: Cash & CBK Balances | B25: =63774068 -> 63774068
A26: Equity Value | B26: =B23+B24+B25 -> 1.6578336e+08
A27: Shares Outstanding ('000) | B27: =1647519 -> 1647519
A28: DCF Fair Value per Share (KES) | B28: =B26/B27 -> 100.62607
A30: Current Market Price (KES) | B30: =Assumptions!$B$40 -> 39.5
A31: Upside / (Downside) to DCF Value | B31: =(B28-B30)/B30 -> 1.5474954

Sheet Multiples Valuation
A1: NCBA GROUP PLC — MULTIPLES & COMPARABLE COMPANY VALUATION
A2: All values KES '000 except per-share | FY2025 Actuals & FY2026E Projections
A4: NCBA FINANCIAL INPUTS (FY2025 ACTUALS & FY2026E)
A5: Financial Metric | B5: FY2025A | C5: FY2026E | D5: Source | E5: Note
A6: Net Profit (PAT) | B6: ='Income Statement'!C33 -> 23393518 | C6: ='Income Statement'!D33 -> 28626840 | D6: Income Statement | E6: KES '000
A7: Net Operating Income | B7: ='Income Statement'!C20 -> 71831953 | C7: ='Income Statement'!D20 -> 82820941 | D7: Income Statement | E7: KES '000
A8: Profit Before Tax (PBT) | B8: ='Income Statement'!C31 -> 27890230 | C8: ='Income Statement'!D31 -> 34120191 | D8: Income Statement | E8: KES '000
A9: Total Equity (Book Value) | B9: ='Balance Sheet'!C30 -> -29015 | C9: ='Balance Sheet'!D30 -> -30465.75 | D9: Balance Sheet | E9: KES '000
A10: Total Assets | B10: ='Balance Sheet'!C15 -> 13371310 | C10: ='Balance Sheet'!D15 -> 13371310 | D10: Balance Sheet | E10: KES '000
A11: EPS (KES) | B11: ='Income Statement'!C36 -> 14.2 | C11: ='Income Statement'!D36 -> 17.375727 | D11: Income Statement | E11: Per share
A12: DPS — Total (KES) | B12: ='Income Statement'!C37 -> 7.1 | C12: ='Income Statement'!D37 -> 10.425436 | D12: Income Statement | E12: Per share
A13: Shares Outstanding ('000) | B13: =1647519 -> 1647519 | C13: =1647519 -> 1647519 | D13: NCBA AR Note 20
A14: Market Price (KES) | B14: =Assumptions!$B$40 -> 39.5 | C14: =Assumptions!$B$40 -> 39.5 | D14: NSE / Assumptions | E14: Current
A15: Market Capitalisation | B15: =B14*B13 -> 65077000 | C15: =C14*C13 -> 65077000 | D15: Calculated | E15: KES '000
A16: Net Debt (Debt - Cash) | B16: =7565293-63774068 -> -56208775 | C16: =7565293-63774068 -> -56208775 | D16: Balance Sheet | E16: KES '000
A17: Enterprise Value (EV) | B17: =B15+B16 -> 8868225.5 | C17: =C15+C16 -> 8868225.5 | D17: Calculated | E17: KES '000
A19: MULTIPLE-BASED VALUATION TABLE
A20: Methodology | B20: Multiple Used | C20: Financial Base (FY25A) | D20: Implied Equity Value | E20: Implied Price/Share (KES) | F20: Prem/(Disc) to Market
A21: P/E — Trailing (FY2025A) | B21: =Assumptions!$B$41 -> 8 | C21: =B6 -> 23393518 | D21: =B21*C21 -> 187148144 | E21: =D21/B13 -> 113.59392 | F21: =(E21-B14)/B14 -> 1.8757955
A22: P/E — Forward (FY2026E) | B22: =Assumptions!$B$41 -> 8 | C22: =C6 -> 28626840 | D22: =B22*C22 -> 2.2901472e+08 | E22: =D22/B13 -> 139.00581 | F22: =(E22-B14)/B14 -> 2.5191345
A23: Price / Book Value (P/B) | B23: =Assumptions!$B$42 -> 1.2 | C23: =B9 -> -29015 | D23: =B23*C23 -> -34818 | E23: =D23/B13 -> -0.021133595 | F23: =(E23-B14)/B14 -> -1.000535
A24: EV / EBITDA | B24: =Assumptions!$B$43 -> 5.5 | C24: =Assumptions!$B$35*B6/(Assumptions!$B$36) -> 15983149 | D24: =B24*C24 -> 87907319 | E24: =D24/B13 -> 53.357393 | F24: =(E24-B14)/B14 -> 0.35082008
A25: Dividend Yield (Gordon) | B25: =Assumptions!$B$44 -> 0.055 | C25: =B12 -> 7.1 | D25: =C25*B13/B25 -> 2.1267973e+08 | E25: =D25/B13 -> 129.09091 | F25: =(E25-B14)/B14 -> 2.2681243
A27: Average Fair Value per Share (KES) | E27: =AVERAGE(E21:E25) -> 87.005381
A28: Minimum Fair Value per Share (KES) | E28: =MIN(E21:E25) -> -0.021133595
A29: Maximum Fair Value per Share (KES) | E29: =MAX(E21:E25) -> 139.00581

Sheet Returns & MOIC
A1: NCBA GROUP PLC — INVESTMENT RETURNS: IRR, NPV, ROI & MOIC
A2: Based on 5-year equity investment horizon FY2026–FY2030 | KES '000
A4: SECTION A: INVESTMENT CASH FLOW TIMELINE
A5: Cash Flow Component | B5: Year 0 (Entry) | C5: Year 1 (FY2026E) | D5: Year 2 (FY2027E) | E5: Year 3 (FY2028E) | F5: Year 4 (FY2029E) | G5: Year 5 (FY2030E)
A6: Initial Equity Investment (Entry) | B6: =-Assumptions!$B$40*1647519 -> -65077000 | C6: 0 | D6: 0 | E6: 0 | F6: 0 | G6: 0
A7: Annual Dividends Received | B7: 0 | C7: ='Income Statement'!D37*1647519 -> 17176104 | D7: ='Income Statement'!E37*1647519 -> 18644946 | E7: ='Income Statement'!F37*1647519 -> 20245560 | F7: ='Income Statement'!G37*1647519 -> 22671713 | G7: ='Income Statement'!H37*1647519 -> 25368734
A8: Exit Equity Proceeds (Year 5) | B8: 0 | C8: 0 | D8: 0 | E8: 0 | F8: 0 | G8: =Assumptions!$B$45*'Income Statement'!H33 -> 3.3824978e+08
A9: NET CASH FLOW (Investor Perspective) | B9: =B6+B7+B8 -> -65077000 | C9: =C6+C7+C8 -> 17176104 | D9: =D6+D7+D8 -> 18644946 | E9: =E6+E7+E8 -> 20245560 | F9: =F6+F7+F8 -> 22671713 | G9: =G6+G7+G8 -> 3.6361852e+08
A11: SECTION B: RETURN METRICS SUMMARY
A12: Internal Rate of Return (IRR) | C12: =IFERROR(IRR(B9:G9),"Check CF") -> 0.57325623
A13: Net Present Value (NPV) | C13: =NPV(Assumptions!$B$39,C9:G9)+B9 -> 1.8027715e+08
A14: NPV Per Share (KES) | C14: =C12/1647519 -> 3.4795121e-07
A15: Return on Investment (ROI) | C15: =(SUM(C9:G9)+B9)/ABS(B9) -> 5.7974374
A16: MOIC (Money-on-Investment) | C16: =IFERROR(G8/ABS(B6),"N/A") -> 5.1976855
A17: Investment Period (Years) | C17: =5 -> 5
A18: Equity Invested (KES '000) | C18: =ABS(B6) -> 65077000
A19: Total Value at Exit (KES '000) | C19: =G8+SUM(C7:G7) -> 4.4235684e+08
A20: Gross IRR (MOIC^(1/Years) - 1) | C20: =IFERROR(POWER(C16,1/C17)-1,"N/A") -> 0.39047121
A22: SECTION C: ROE, ROA & EFFICIENCY — HISTORICAL & PROJECTED
A23: Ratio | B23: FY2024A | C23: FY2025A | D23: FY2026E | E23: FY2027E | F23: FY2028E | G23: FY2029E | H23: FY2030E
A24: Return on Equity (ROE) | B24: 0.1993 | C24: 0.1971 | D24: =C24*1.02 -> 0.201042 | E24: =D24*1.02 -> 0.20506284 | F24: =E24*1.02 -> 0.2091641 | G24: =F24*1.02 -> 0.21334738 | H24: =G24*1.02 -> 0.21761433
A25: Return on Assets (ROA) | B25: 0.0329 | C25: 0.0327 | D25: =C25*1.02 -> 0.033354 | E25: =D25*1.02 -> 0.03402108 | F25: =E25*1.02 -> 0.034701502 | G25: =F25*1.02 -> 0.035395532 | H25: =G25*1.02 -> 0.036103442
A26: Net Interest Margin (NIM) | B26: 0.077 | C26: 0.087 | D26: =C26 -> 0.087 | E26: =D26 -> 0.087 | F26: =E26 -> 0.087 | G26: =F26 -> 0.087 | H26: =G26 -> 0.087
A27: Cost-to-Income Ratio | B27: 0.5145 | C27: 0.517 | D27: =C27 -> 0.517 | E27: =D27 -> 0.517 | F27: =E27 -> 0.517 | G27: =F27 -> 0.517 | H27: =G27 -> 0.517
A28: EPS (KES) | B28: 13.28 | C28: 14.2 | D28: ='Income Statement'!D36 -> 17.375727 | E28: ='Income Statement'!E36 -> 18.86164 | F28: ='Income Statement'!F36 -> 20.480857 | G28: ='Income Statement'!G36 -> 22.935206 | H28: ='Income Statement'!H36 -> 25.663572
A29: DPS (KES) | B29: 5.5 | C29: 7.1 | D29: ='Income Statement'!D37 -> 10.425436 | E29: ='Income Statement'!E37 -> 11.316984 | F29: ='Income Statement'!F37 -> 12.288514 | G29: ='Income Statement'!G37 -> 13.761124 | H29: ='Income Statement'!H37 -> 15.398143
A30: Dividend Payout Ratio | B30: 0.4143 | C30: 0.5 | D30: =C30 -> 0.5 | E30: =D30 -> 0.5 | F30: =E30 -> 0.5 | G30: =F30 -> 0.5 | H30: =G30 -> 0.5
A31: NPL / Gross Loans (Stage 3) | B31: 0.0855 | C31: 0.0745 | D31: =C31 -> 0.0745 | E31: =D31 -> 0.0745 | F31: =E31 -> 0.0745 | G31: =F31 -> 0.0745 | H31: =G31 -> 0.0745
A32: Loan-to-Deposit Ratio | B32: 0.5854 | C32: 0.5771 | D32: =C32 -> 0.5771 | E32: =D32 -> 0.5771 | F32: =E32 -> 0.5771 | G32: =F32 -> 0.5771 | H32: =G32 -> 0.5771

Sheet Sensitivity Analysis
A1: NCBA GROUP PLC — SENSITIVITY ANALYSIS (WHAT-IF TABLES)
A2: Two-variable sensitivity tables — change inputs to see effect on key outputs
A4: TABLE 1: DCF VALUE PER SHARE (KES) — WACC (rows) vs Terminal Growth Rate (cols)
A5: WACC ↓ / Growth → | B5: 2.5% | C5: 3.0% | D5: 3.5% | E5: 4.0% | F5: 4.5% | G5: 5.0% | H5: 5.5% | I5: 6.0%
A6: 11% | B6: 221.91 | C6: 230.59 | D6: 240.42 | E6: 251.66 | F6: 264.63 | G6: 279.76 | H6: 297.64 | I6: 319.1
A7: 12% | B7: 201.92 | C7: 208.57 | D7: 216.02 | E7: 224.39 | F7: 233.87 | G7: 244.72 | H7: 257.23 | I7: 271.83
A8: 13% | B8: 185.75 | C8: 190.98 | D8: 196.76 | E8: 203.19 | F8: 210.37 | G8: 218.45 | H8: 227.6 | I8: 238.07
A9: 14% | B9: 172.4 | C9: 176.59 | D9: 181.18 | E9: 186.24 | F9: 191.82 | G9: 198.02 | H9: 204.95 | I9: 212.75
A10: 15% | B10: 161.2 | C10: 164.62 | D10: 168.33 | E10: 172.37 | F10: 176.81 | G10: 181.69 | H10: 187.08 | I10: 193.07
A11: 16% | B11: 151.67 | C11: 154.49 | D11: 157.53 | E11: 160.83 | F11: 164.42 | G11: 168.33 | H11: 172.61 | I11: 177.32
A12: 17% | B12: 143.46 | C12: 145.82 | D12: 148.35 | E12: 151.07 | F12: 154.01 | G12: 157.2 | H12: 160.66 | I12: 164.44
A13: 18% | B13: 136.32 | C13: 138.31 | D13: 140.43 | E13: 142.71 | F13: 145.15 | G13: 147.79 | H13: 150.63 | I13: 153.71
A15: TABLE 2: NET PROFIT PAT FY2026E (KES bn) — NII Growth (rows) vs OpEx Growth (cols)
A16: NII Gr ↓ / OpEx → | B16: 6% | C16: 8% | D16: 10% | E16: 12% | F16: 14% | G16: 16% | H16: 18%
A17: 4% | B17: 0.02 | C17: 0.02 | D17: 0.02 | E17: 0.02 | F17: 0.02 | G17: 0.02 | H17: 0.02
A18: 6% | B18: 0.02 | C18: 0.02 | D18: 0.02 | E18: 0.02 | F18: 0.02 | G18: 0.02 | H18: 0.02
A19: 8% | B19: 0.03 | C19: 0.02 | D19: 0.02 | E19: 0.02 | F19: 0.02 | G19: 0.02 | H19: 0.02
A20: 10% | B20: 0.03 | C20: 0.03 | D20: 0.03 | E20: 0.02 | F20: 0.02 | G20: 0.02 | H20: 0.02
A21: 12% | B21: 0.03 | C21: 0.03 | D21: 0.03 | E21: 0.03 | F21: 0.02 | G21: 0.02 | H21: 0.02
A22: 14% | B22: 0.03 | C22: 0.03 | D22: 0.03 | E22: 0.03 | F22: 0.03 | G22: 0.03 | H22: 0.02
A23: 16% | B23: 0.03 | C23: 0.03 | D23: 0.03 | E23: 0.03 | F23: 0.03 | G23: 0.03 | H23: 0.03
A25: TABLE 3: MOIC — Entry P/E Multiple (rows) vs Exit P/E Multiple (cols)
A26: Entry P/E ↓ / Exit → | B26: 4x | C26: 5x | D26: 6x | E26: 7x | F26: 8x | G26: 9x | H26: 10x | I26: 11x
A27: 4x | B27: 1.54 | C27: 1.92 | D27: 2.31 | E27: 2.69 | F27: 3.08 | G27: 3.46 | H27: 3.85 | I27: 4.23
A28: 5x | B28: 1.23 | C28: 1.54 | D28: 1.85 | E28: 2.15 | F28: 2.46 | G28: 2.77 | H28: 3.08 | I28: 3.38
A29: 6x | B29: 1.03 | C29: 1.28 | D29: 1.54 | E29: 1.8 | F29: 2.05 | G29: 2.31 | H29: 2.56 | I29: 2.82
A30: 7x | B30: 0.88 | C30: 1.1 | D30: 1.32 | E30: 1.54 | F30: 1.76 | G30: 1.98 | H30: 2.2 | I30: 2.42
A31: 8x | B31: 0.77 | C31: 0.96 | D31: 1.15 | E31: 1.35 | F31: 1.54 | G31: 1.73 | H31: 1.92 | I31: 2.12
A32: 9x | B32: 0.68 | C32: 0.85 | D32: 1.03 | E32: 1.2 | F32: 1.37 | G32: 1.54 | H32: 1.71 | I32: 1.88
A33: 10x | B33: 0.62 | C33: 0.77 | D33: 0.92 | E33: 1.08 | F33: 1.23 | G33: 1.38 | H33: 1.54 | I33: 1.69
A34: 11x | B34: 0.56 | C34: 0.7 | D34: 0.84 | E34: 0.98 | F34: 1.12 | G34: 1.26 | H34: 1.4 | I34: 1.54
A36: TABLE 4: DIVIDEND YIELD VALUATION — DPS FY2026E (rows) vs Required Yield (cols)
A37: DPS (KES) ↓ / Yield → | B37: 4% | C37: 5% | D37: 6% | E37: 7% | F37: 8% | G37: 9% | H37: 10%
A38: KES 5.0 | B38: 125 | C38: 100 | D38: 83.33 | E38: 71.43 | F38: 62.5 | G38: 55.56 | H38: 50
A39: KES 5.5 | B39: 137.5 | C39: 110 | D39: 91.67 | E39: 78.57 | F39: 68.75 | G39: 61.11 | H39: 55
A40: KES 6.0 | B40: 150 | C40: 120 | D40: 100 | E40: 85.71 | F40: 75 | G40: 66.67 | H40: 60
A41: KES 6.5 | B41: 162.5 | C41: 130 | D41: 108.33 | E41: 92.86 | F41: 81.25 | G41: 72.22 | H41: 65
A42: KES 7.0 | B42: 175 | C42: 140 | D42: 116.67 | E42: 100 | F42: 87.5 | G42: 77.78 | H42: 70
A43: KES 7.5 | B43: 187.5 | C43: 150 | D43: 125 | E43: 107.14 | F43: 93.75 | G43: 83.33 | H43: 75
A44: KES 8.0 | B44: 200 | C44: 160 | D44: 133.33 | E44: 114.29 | F44: 100 | G44: 88.89 | H44: 80
...

Sheet Summary & Recommendation
A1: NCBA GROUP PLC — INVESTMENT SUMMARY & RECOMMENDATION
A2: NSE: NCBA | Banking & Financial Services | Nairobi Securities Exchange
A4: COMPANY SNAPSHOT
A5: Company | B5: NCBA Group PLC
A6: Ticker | B6: NSE: NCBA
A7: Sector | B7: Banking & Financial Services
A8: Current Price (KES) | B8: =Assumptions!$B$40 -> 39.5
A9: Date of Analysis | B9: 31-Dec-2025
A10: Report Basis | B10: FY2025 Annual Report & Financial Statements
A12: VALUATION SUMMARY
A13: Valuation Method | B13: Fair Value (KES) | C13: Current Price | D13: Upside/(Downside) | E13: Weight
A14: DCF Valuation (FCFE) | B14: ='DCF Valuation'!B28 -> 100.62607 | C14: =Assumptions!$B$40 -> 39.5 | D14: =(B14-C14)/C14 -> 1.5474954 | E14: 0.4
A15: P/E Multiple (Trailing) | B15: ='Multiples Valuation'!E21 -> 113.59392 | C15: =Assumptions!$B$40 -> 39.5 | D15: =(B15-C15)/C15 -> 1.8757955 | E15: 0.2
A16: P/E Multiple (Forward) | B16: ='Multiples Valuation'!E22 -> 139.00581 | C16: =Assumptions!$B$40 -> 39.5 | D16: =(B16-C16)/C16 -> 2.5191345 | E16: 0.2
A17: Price/Book (P/B) | B17: ='Multiples Valuation'!E23 -> -0.021133595 | C17: =Assumptions!$B$40 -> 39.5 | D17: =(B17-C17)/C17 -> -1.000535 | E17: 0.1
A18: Dividend Yield (Gordon) | B18: ='Multiples Valuation'!E25 -> 129.09091 | C18: =Assumptions!$B$40 -> 39.5 | D18: =(B18-C18)/C18 -> 2.2681243 | E18: 0.1
A19: WEIGHTED AVERAGE FAIR VALUE | B19: =SUMPRODUCT(B14:B18,E14:E18)/SUM(E14:E18) -> 103.67735 | D19: =(B19-Assumptions!$B$40)/Assumptions!$B$40 -> 1.6247431
A21: KEY FINANCIAL METRICS (FY2025 ACTUAL)
A22: Net Interest Income (KES bn) | B22: =57712/1000 -> 57.712
A23: Net Profit / PAT (KES bn) | B23: ='Income Statement'!C33/1000000 -> 23.393518
A24: Total Assets (KES bn) | B24: ='Balance Sheet'!C15/1000000 -> 13.37131
A25: Customer Deposits (KES bn) | B25: ='Balance Sheet'!C19/1000000 -> 531.86622
A26: Net Loans (KES bn) | B26: ='Balance Sheet'!C11/1000000 -> 306.91798
A27: EPS (KES) | B27: =14.2 -> 14.2
A28: DPS Total (KES) | B28: =7.1 -> 7.1
A29: ROE | B29: =0.1971 -> 0.1971
A30: ROA | B30: =0.0327 -> 0.0327
A31: Cost-to-Income | B31: =0.517 -> 0.517
A32: NIM | B32: =0.087 -> 0.087
A33: Dividend Yield | B33: =7.1/Assumptions!$B$40 -> 0.17974684
A35: INVESTMENT RECOMMENDATION
A36: Recommendation: | B36: =IF((B19-Assumptions!$B$40)/Assumptions!$B$40>0.2,"STRONG BUY",IF((B19-Assumptions!$B$40)/Assumptions!$B$40>0.1,"BUY",IF((B19-Assumptions!$B$40)/Assumptions!$B$40>0,"HOLD",IF((B19-Assumptions!$B$40)/Assumptions!$B$40>-0.1,"UNDERPERFORM","SELL")))) -> STRONG BUY
A37: Target Price (Weighted Avg, KES): | B37: =B19 -> 103.67735
A38: Potential Return (%): | B38: =(B19-Assumptions!$B$40)/Assumptions!$B$40 -> 1.6247431
A40: INVESTMENT THESIS
A41: Strengths: | C41: Risks:
A42: • FY2025 PBT of KES 27.9 bn, +11% YoY — consistent earnings growth | C42: • Credit impairment losses rose 37% to KES 6.9 bn — NPL risk persists
A43: • Net Interest Income surged KES 10.3 bn driven by deposit repricing discipline | C43: • Operating expenses rose 16% (KES 5.2 bn) — cost pressure from headcount
A44: • Strong digital banking franchise — Loop DFS, NCBA Loop, M-Shwari ecosystem | C44: • Interest income declined KES 6.9 bn as market rates eased (CBK cuts)
A45: • Total Assets of KES 716 bn; deposits grew 6% to KES 532 bn | C45: • FX volatility across regional subsidiaries
...
